<mujoco model="legwheel2">
    <include file="./common/skybox.xml"/>
    <include file="./common/visual.xml"/>
    <include file="./common/materials.xml"/>
    
    <option gravity="0 0 -9.8" timestep="0.002" wind="0 0 0" integrator="Euler" />
    <default>
        <default class="leg">
            <!-- <joint armature="0.001" damping="1" stiffness="0" /> -->
            <!-- <joint damping="0.1" stiffness="0" armature="0.001" limited="true" solimplimit="0 .99 .01" range="-90 90" /> -->
            <joint damping=".01" stiffness="1" armature=".001" />
        </default>
        <default class="wheel">
            <joint armature="0.001" damping="0.01" stiffness="0." />
        </default>
    </default>
    <worldbody>
        <geom name="floor" pos="0 0 -.05" size="10 10 .2" type="plane" material="grid"/>
        <body name="root" pos="0 0 0.109" euler="0 0 0">
            <freejoint name="root_joint" />
            <site name="root" pos="0 0 0.03" size="0.01" rgba="0 0 0 1"/>
            <geom size="0.05 0.05 0.03" type="box" rgba="0 0 0.8 1"  material="self"/>
            <geom size="0.03 0.03 0.0177" type="box" rgba="0 0.8 0.8 1"  material="self" pos="0.047 0 0" />
            <body name="thigh_left" pos="-0.031 0.06 -0.04" euler="0 40 0" >
                <joint name="thigh_left_joint" type="hinge" pos="0 0 0.05" axis="0 1 0" class="leg" />
                <geom size="0.01 0.01 0.055" type="box" rgba="0 0.8 0. 0.5"  material="self"/>
                <body name="calf_left" pos="0.03 0. -0.05" euler="0 -90 0">
                    <joint name="calf_left_joint" type="hinge" pos="0 0 0.03" axis="0 1 0" class="leg" />
                    <geom size="0.01 0.01 0.06" type="box" rgba="0.8 0.8 0. 0.5"  material="self"/>
                    <body name="rod_left" pos="0.045 0 0.066" euler="0 75 0" >
                        <joint name="rod_left_joint" type="hinge" pos="0 0 -0.045" axis="0 1 0" class="leg" />
                        <geom size="0.003 0.009 0.05" type="box" rgba="0 0.0 0.0 0.5"  material="self"/>
                    </body>
                    <body name="wheel_left" pos="0. 0.02 -0.05" euler="90 0 0">
                        <joint name="wheel_left_joint" type="hinge" pos="0 0 0" axis="0 0 -1" class="wheel" />
                        <geom size="0.03 0.01" type="cylinder" rgba="0.8 0 0 1"  material="self"/>
                        <geom size="0.001 0.02 0.001" type="box" rgba="0.8 0.8 0.8 1"  material="self" pos="0 0 -0.01" />
                    </body>
                </body>
            </body>
            
            <body name="thigh_right" pos="-0.031 -0.06 -0.04" euler="0 40 0" >
                <joint name="thigh_right_joint" type="hinge" pos="0 0 0.05" axis="0 1 0" class="leg" />
                <geom size="0.01 0.01 0.055" type="box" rgba="0 0.8 0. 0.5"  material="self"/>
                <body name="calf_right" pos="0.03 0. -0.05" euler="0 -90 0">
                    <joint name="calf_right_joint" type="hinge" pos="0 0 0.03" axis="0 1 0" class="leg" />
                    <geom size="0.01 0.01 0.06" type="box" rgba="0.8 0.8 0. 0.5"  material="self"/>
                    <body name="rod_right" pos="0.045 0 0.066" euler="0 75 0" >
                        <joint name="rod_right_joint" type="hinge" pos="0 0 -0.045" axis="0 1 0" class="leg" />
                        <geom size="0.003 0.009 0.05" type="box" rgba="0 0.0 0.0 0.5"  material="self"/>
                    </body>
                    <body name="wheel_right" pos="0. -0.02 -0.05" euler="90 0 0">
                        <joint name="wheel_right_joint" type="hinge" pos="0 0 0" axis="0 0 -1" class="wheel" />
                        <geom size="0.03 0.01" type="cylinder" rgba="0.8 0 0 1"  material="self"/>
                        <geom size="0.001 0.02 0.001" type="box" rgba="0.8 0.8 0.8 1"  material="self" pos="0 0 0.01" />
                    </body>
                </body>
            </body>
        </body>
    </worldbody>
    <equality>
        <connect body1="root" body2="rod_left" anchor="-0.043 0.06 0.02"/>
        <connect body1="root" body2="rod_right" anchor="-0.043 -0.06 0.02"/>
    </equality>
    <actuator>
        <!-- <motor name="thigh_left_motor" joint="thigh_left_joint" gear="0.1" />
        <motor name="thigh_right_motor" joint="thigh_right_joint" gear="0.1" /> -->
        <position name="thigh_left_pos" joint="thigh_left_joint" kp="10" ctrllimited="true" ctrlrange="-0.2 0.5" />
        <position name="thigh_right_pos" joint="thigh_right_joint" kp="10" ctrllimited="true" ctrlrange="-0.2 0.5" />

        <motor name="wheel_left_motor" joint="wheel_left_joint" gear="1" ctrllimited="true" ctrlrange="-1.0 1.0" />
        <motor name="wheel_right_motor" joint="wheel_right_joint" gear="1" ctrllimited="true" ctrlrange="-1.0 1.0" />
    </actuator>
    <!-- <sensor>
        <gyro name="gyro" site="root"/>
        <accelerometer name="accel" site="root"/>

        <actuatorpos name="wheel_left_pos" actuator="wheel_left_motor" />
        <actuatorpos name="wheel_right_pos" actuator="wheel_right_motor" />
        <actuatorvel name="wheel_left_vel" actuator="wheel_left_motor" />
        <actuatorvel name="wheel_right_vel" actuator="wheel_right_motor" />
    </sensor> -->
</mujoco>