<mujoco model="legwheel">
    <include file="./common/skybox.xml"/>
    <include file="./common/visual.xml"/>
    <include file="./common/materials.xml"/>
    
    <option gravity="0 0 -9.8"/>
    <worldbody>
        <camera pos="4.362 6.481 5.950" xyaxes="-0.808 0.589 0.000 -0.324 -0.444 0.835"/>
        <geom name="floor" pos="0 0 -.05" size="10 10 .2" type="plane" material="grid"/>
        <body name="root" pos="0 0 1.249">
            <joint name="root_joint" type="free"/>
            <site name="root" pos="0 0 0.3" size="0.1" rgba="0 0 0 1"/>
            <geom size="0.5 0.5 0.3" type="box" rgba="0 0 0.8 1"  material="self"/>
            <body name="leg_left" pos="0 0.6 -0.5">
                <!-- <joint name="leg_left_joint" type="hinge" pos="0 0 0.5" axis="0 1 0"/> -->
                <geom size="0.1 0.1 0.5" type="box" rgba="0 0.8 0. 0.5"  material="self"/>
                <body name="wheel_left" pos="0. 0.2 -0.5" euler="90 0 0">
                    <joint name="wheel_left_joint" type="hinge" pos="0 0 0" axis="0 0 -1"/>
                    <geom size="0.3 0.1" type="cylinder" rgba="0.8 0 0 1"  material="self"/>
                </body>
            </body>
            <body name="leg_right" pos="0 -0.6 -0.5">
                <!-- <joint name="leg_right_joint" type="hinge" pos="0 0 0.5" axis="0 1 0"/> -->
                <geom size="0.1 0.1 0.5" type="box" rgba="0 0.8 0. 0.5"  material="self"/>
                <body name="wheel_right" pos="0. -0.2 -0.5" euler="90 0 0">
                    <joint name="wheel_right_joint" type="hinge" pos="0 0 0" axis="0 0 -1"/>
                    <geom size="0.3 0.1" type="cylinder" rgba="0.8 0 0 1"  material="self"/>
                </body>
            </body>
        </body>
    </worldbody>

    <actuator>
        <!-- <position name="leg_left_pos" joint="leg_left_joint" kp="0" dampratio="100" /> -->
        <!-- <position name="leg_right_pos" joint="leg_right_joint" kp="0" dampratio="100" /> -->

        <!-- <position name="wheel_left_pos" joint="wheel_left_joint" kp="0" />
        <position name="wheel_right_pos" joint="wheel_right_joint" kp="0" />
        <velocity name="wheel_left_vel" joint="wheel_left_joint" kv="1000" />
        <velocity name="wheel_right_vel" joint="wheel_right_joint" kv="1000" /> -->

        <motor name="wheel_left_motor" joint="wheel_left_joint" />
        <motor name="wheel_right_motor" joint="wheel_right_joint" />
    </actuator>
    <sensor>
        <gyro name="gyro" site="root"/>
        <accelerometer name="accel" site="root"/>

        <actuatorpos name="wheel_left_pos" actuator="wheel_left_motor" />
        <actuatorpos name="wheel_right_pos" actuator="wheel_right_motor" />
        <actuatorvel name="wheel_left_vel" actuator="wheel_left_motor" />
        <actuatorvel name="wheel_right_vel" actuator="wheel_right_motor" />
    </sensor>
</mujoco>